{"root":{"data":{"id":"da4vtxd5nu00","created":1748139773774,"text":"牛客测练200题"},"children":[{"data":{"id":"da4vuad6ek00","created":1748139802073,"text":"异常类(代码运行逻辑)："},"children":[{"data":{"id":"da4wfvvk8j40","created":1748141494544,"text":"关于 try-catch-finally"},"children":[{"data":{"id":"da4wg0iils80","created":1748141504640,"text":"需知："},"children":[{"data":{"id":"da4wha2c5zc0","created":1748141603793,"text":"捕捉异常"},"children":[{"data":{"id":"da4wg7v56g00","created":1748141520641,"text":"try{ int f=1/0 ; 打印1 }"},"children":[{"data":{"id":"da4wgmqonow0","created":1748141553023,"text":"将不会执行 “打印1”"},"children":[]}]},{"data":{"id":"da4wgyhobeg0","created":1748141578599,"text":"catch(Exception e){ int f=1/0 ; 打印2 }"},"children":[{"data":{"id":"da4wh48xavc0","created":1748141591131,"text":"将不会执行“打印2”"},"children":[]}]},{"data":{"id":"da4whdt0djc0","created":1748141611936,"text":"即是，异常在try 与 catch中，都可以被捕捉"},"children":[]},{"data":{"id":"da4whpsp1ao0","created":1748141638039,"text":"但仅限出现一次，不能两个都存在异常"},"children":[]},{"data":{"id":"da4whxs7dxc0","created":1748141655423,"text":"既然可以捕捉，也就只有对应异常的那部分不能正常执行"},"children":[]}]}]}]}]}]},"template":"default","theme":"classic","version":"1.4.43"}